<?xml version="1.0"?>

<robot name="arm" xmlns:xacro="http://www.ros.org/wiki/xacro">

  <!--The lift xacro macro-->
  <macro name="lift" params="parent name color">
    <joint name="joint_${name}" type="prismatic">
      <origin xyz="-0.04456 0.00022708 0.72985" rpy="-2.7756E-17 0 -1.5708" />
      <parent link="${parent}_link" />
      <child  link="link_${name}" />
      <axis xyz="0 0 -1" />
      <limit lower="-0.15" upper="0.15" effort="500" velocity="1" />
    </joint>

    <link name="link_${name}">
       <inertial>
         <origin xyz="-8.3267E-17 0.048515 0.0020048" rpy="0 0 0" />
         <mass value="1.7076" />
         <inertia ixx="0.015015" ixy="2.1531E-18" ixz="-3.952E-19"
                  iyy="0.015774" iyz="-8.1536E-05" izz="0.0028516" />
      </inertial>
      <visual>
        <origin xyz="0 0 0" rpy="0 0 0" />
        <geometry>
          <mesh filename="package://xm_arm_description/meshes/link_${name}.stl" />
        </geometry>
        <material name="${color}" />
      </visual>
      <collision>
        <origin xyz="0 0 0" rpy="0 0 0" />
        <geometry>
          <mesh filename="package://xm_arm_description/meshes/link_${name}_l.stl" />
        </geometry>
      </collision>
    </link>
  </macro>

  <!--The waist xacro macro-->
  <macro name="waist" params="parent name color">
    <joint name="joint_${name}" type="revolute">
      <origin xyz="0 0.0945 0.00415" rpy="2.7756E-17 1.3056E-31 -2.8372E-16" />
      <parent link="link_${parent}" />
      <child  link="link_${name}" />
      <axis xyz="0 0 1" />
      <limit lower="-1.047" upper="1.047" effort="500" velocity="1" />
    </joint>

    <link name="link_${name}">
      <inertial>
        <origin xyz="0.00035629 0.050223 0.014835" rpy="0 0 0" />
        <mass value="2.2632" />
        <inertia ixx="0.014881" ixy="2.8517E-05" ixz="-0.00013888"
                 iyy="0.015217" iyz="0.00052947" izz="0.0095668" />
      </inertial>
      <visual>
        <origin xyz="0 0 0" rpy="0 0 0" />
        <geometry>
          <mesh filename="package://xm_arm_description/meshes/link_${name}.stl" />
        </geometry>
        <material name="${color}" />
      </visual>
      <collision>
        <origin xyz="0 0 0" rpy="0 0 0" />
        <geometry>
          <mesh filename="package://xm_arm_description/meshes/link_${name}_l.stl" />
        </geometry>
      </collision>
    </link>
  </macro>

  <!--The big_arm xacro macro-->
  <macro name="big_arm" params="parent name color">
    <joint name="joint_${name}" type="revolute">
      <origin xyz="0 0.15678 -0.018" rpy="1.5708 -7.7037E-34 1.5708" />
      <parent link="link_${parent}" />
      <child  link="link_${name}" />
      <axis xyz="0 0 1" />
      <limit lower="-1.920" upper="1.396" effort="500" velocity="1" />
    </joint>

    <link name="link_${name}">
      <inertial>
        <origin xyz="0.095008 0.006168 0.0026321" rpy="0 0 0" />
        <mass value="1.2241" />
        <inertia ixx="0.0030013" ixy="0.00024375" ixz="0.0004659"
                 iyy="0.017469" iyz="-1.9873E-05" izz="0.015447" />
      </inertial>
      <visual>
        <origin xyz="0 0 0" rpy="0 0 0" />
        <geometry>
          <mesh filename="package://xm_arm_description/meshes/link_${name}.stl" />
        </geometry>
        <material name="${color}" />
      </visual>
      <collision>
        <origin xyz="0 0 0" rpy="0 0 0" />
        <geometry>
          <mesh filename="package://xm_arm_description/meshes/link_${name}_l.stl" />
        </geometry>
      </collision>
    </link>
  </macro>

  <!--The forearm xacro macro-->
  <macro name="forearm" params="parent name color">
    <joint name="joint_${name}" type="revolute">
      <origin xyz="0.35 0 0" rpy="-6.4095E-31 2.2204E-16 -7.7037E-34" />
      <parent link="link_${parent}" />
      <child  link="link_${name}" />
      <axis xyz="0 0 -1" />
      <limit lower="-2.234" upper="2.234" effort="500" velocity="1" />
    </joint>

    <link name="link_${name}">
      <inertial>
        <origin xyz="0.099759 -2.2204E-16 0.00013669" rpy="0 0 0" />
        <mass value="0.70102" />
        <inertia ixx="0.00073291" ixy="5.0551E-18" ixz="4.274E-05"
                 iyy="0.0069521" iyz="7.8112E-19" izz="0.0066437" />
      </inertial>
      <visual>
        <origin xyz="0 0 0" rpy="0 0 0" />
        <geometry>
          <mesh filename="package://xm_arm_description/meshes/link_${name}.stl" />
        </geometry>
        <material name="${color}" />
      </visual>
      <collision>
        <origin xyz="0 0 0" rpy="0 0 0" />
        <geometry>
          <mesh filename="package://xm_arm_description/meshes/link_${name}_l.stl" />
        </geometry>
      </collision>
    </link>
  </macro>

  <!--The wristing_pitching xacro macro-->
  <macro name="wrist_pitching" params="parent name color">
    <joint name="joint_${name}" type="revolute">
      <origin xyz="0.3 0 0" rpy="0 0 1.5708" />
      <parent link="link_${parent}" />
      <child  link="link_${name}" />
      <axis xyz="0 0 -1" />
      <limit lower="-2.182" upper="2.182" effort="500" velocity="1" />
    </joint>

    <link name="link_${name}">
      <inertial>
        <origin xyz="1.7127E-09 -0.00034153 -1.195E-06" rpy="0 0 0" />
        <mass value="0.037514" />
        <inertia ixx="1.063E-05" ixy="1.0698E-13" ixz="-4.4237E-13"
                 iyy="1.0507E-05" iyz="-1.5531E-11" izz="3.2674E-06" />
      </inertial>
      <visual>
        <origin xyz="0 0 0" rpy="0 0 0" />
        <geometry>
          <mesh filename="package://xm_arm_description/meshes/link_${name}.stl" />
        </geometry>
        <material name="${color}" />
      </visual>
      <collision>
        <origin xyz="0 0 0" rpy="0 0 0" />
        <geometry>
          <mesh filename="package://xm_arm_description/meshes/link_${name}_l.stl" />
        </geometry>
      </collision>
    </link>
  </macro>

  <!--The wristing_rotation xacro macro-->
  <macro name="wrist_rotation" params="parent name color">
    <joint name="joint_${name}" type="continuous">
      <origin xyz="0 0 0" rpy="1.5708 -1.5708 0" />
      <parent link="link_${parent}" />
      <child  link="link_${name}" />
      <axis xyz="0 0 1" />
      <limit effort="500" velocity="1" />
    </joint>

    <link name="link_${name}">
      <inertial>
        <origin xyz="0.00041743 -0.00042922 0.069037" rpy="0 0 0" />
        <mass value="0.12901" />
        <inertia ixx="0.00010496" ixy="-2.1936E-07" ixz="5.5636E-07"
                 iyy="0.00011251" iyz="-1.2571E-06" izz="3.1759E-05" />
      </inertial>
      <visual>
        <origin xyz="0 0 0" rpy="0 0 0" />
        <geometry>
          <mesh filename="package://xm_arm_description/meshes/link_${name}.stl" />
        </geometry>
        <material name="${color}" />
      </visual>
      <collision>
        <origin xyz="0 0 0" rpy="0 0 0" />
        <geometry>
          <mesh filename="package://xm_arm_description/meshes/link_${name}_l.stl" />
        </geometry>
      </collision>
    </link>
  </macro>

</robot>
