<?xml version="1.0" ?>
<!-- =================================================================================== -->
<!-- |    This document was autogenerated by xacro from xmbot_with_arm.xacro           | -->
<!-- |    EDITING THIS FILE BY HAND IS NOT RECOMMENDED                                 | -->
<!-- =================================================================================== -->
<robot name="xmbot" xmlns:xacro="http://www.ros.org/wiki/xacro">
  <!-- The following xacro:include files set up definitions of parts of the robot body -->
  <!-- Put all the color definitions in a separate file -->
  <material name="DarkBlack">
    <color rgba="0.0 0.0 0.0 1.0"/>
  </material>
  <material name="Black">
    <color rgba="0.2 0.2 0.2 1.0"/>
  </material>
  <material name="TransparentBlack">
    <color rgba="0.2 0.2 0.2 0.8"/>
  </material>
  <material name="Orange">
    <color rgba="1.0 0.55 0.0 1.0"/>
  </material>
  <material name="Grey">
    <color rgba="0.7 0.7 0.7 1.0"/>
  </material>
  <material name="DarkGrey">
    <color rgba="0.3 0.3 0.3 1.0"/>
  </material>
  <material name="Red">
    <color rgba="0.8 0.0 0.0 1.0"/>
  </material>
  <material name="White">
    <color rgba="1.0 1.0 1.0 1.0"/>
  </material>
  <material name="OffWhite">
    <color rgba="0.8 0.8 0.8 1.0"/>
  </material>
  <material name="Blue">
    <color rgba="0.0 0.0 0.8 1.0"/>
  </material>
  <material name="Green">
    <color rgba="0.0 0.8 0.0 1.0"/>
  </material>
  <material name="TransparentGreen">
    <color rgba="0.0 0.8 0.0 0.5"/>
  </material>
  <!-- The base xacro macro -->
  <link name="base_footprint">
    <visual>
      <origin rpy="0 0 0" xyz="0 0 0"/>
      <geometry>
        <box size="0.05 0.05 0.001"/>
      </geometry>
      <material name="TransparentGreen"/>
    </visual>
  </link>
  <joint name="base_joint" type="fixed">
    <origin rpy="0 0 0" xyz="0 0 0"/>
    <parent link="base_footprint"/>
    <child link="base_link"/>
  </joint>
  <!-- The wheel xacro macro -->
  <!--The lift xacro macro-->
  <!--The waist xacro macro-->
  <!--The big_arm xacro macro-->
  <!--The forearm xacro macro-->
  <!--The wristing_pitching xacro macro-->
  <!--The wristing_rotation xacro macro-->
  <!--The finger_left xacro macro-->
  <!--The finger_right xacro macro-->
  <!--The gripper_frame xacro macro-->
  <!--The kinect xacro macro-->
  <joint name="kinect_depth_joint" type="fixed">
    <origin rpy="-1.57079632679 0 -1.57079632679" xyz="0 0 0"/>
    <parent link="link_kinect"/>
    <child link="link_kinect_depth"/>
  </joint>
  <link name="link_kinect_depth"/>
  <!--The laser xacro macro-->
  <!-- Attach the base -->
  <link name="base_link">
    <inertial>
      <origin rpy="0 0 0" xyz="-0.030096 -0.00033289 0.43437"/>
      <mass value="28.429"/>
      <inertia ixx="3.3043" ixy="0.00011321" ixz="-0.22301" iyy="3.3216" iyz="0.0036429" izz="0.40235"/>
    </inertial>
    <visual>
      <origin rpy="0 0 0" xyz="0 0 0"/>
      <geometry>
        <mesh filename="package://xm_arm_description/meshes/base_link.stl"/>
      </geometry>
      <material name="DarkGrey"/>
    </visual>
    <collision>
      <origin rpy="0 0 0" xyz="0 0 0"/>
      <geometry>
        <mesh filename="package://xm_arm_description/meshes/base_link_l.stl"/>
      </geometry>
    </collision>
  </link>
  <!-- Add the drive wheels -->
  <joint name="joint_wheel_1" type="fixed">
    <origin rpy="-1.5708 0 -1.5708" xyz="0.19419 0.00022708 -0.042"/>
    <parent link="base_link"/>
    <child link="link_wheel_1"/>
    <axis xyz="0 0 1"/>
  </joint>
  <link name="link_wheel_1">
    <inertial>
      <origin rpy="0 0 0" xyz="8.0491E-16 -1.3878E-17 -0.0042221"/>
      <mass value="0.34065"/>
      <inertia ixx="0.00030696" ixy="-3.4634e-22" ixz="-7.3136e-19" iyy="0.00030696" iyz="8.9342e-21" izz="0.00029643"/>
    </inertial>
    <visual>
      <origin rpy="0 0 0" xyz="0 0 0"/>
      <geometry>
        <mesh filename="package://xm_arm_description/meshes/link_wheel_1.stl"/>
      </geometry>
      <material name="DarkGrey"/>
    </visual>
    <collision>
      <origin rpy="0 0 0" xyz="0 0 0"/>
      <geometry>
        <mesh filename="package://xm_arm_description/meshes/link_wheel_1_l.stl"/>
      </geometry>
    </collision>
  </link>
  <joint name="joint_wheel_2" type="fixed">
    <origin rpy="-1.5708 0 2.618" xyz="-0.096968 -0.16833 -0.042"/>
    <parent link="base_link"/>
    <child link="link_wheel_2"/>
    <axis xyz="0 0 1"/>
  </joint>
  <link name="link_wheel_2">
    <inertial>
      <origin rpy="0 0 0" xyz="-1.3878E-17 1.3878E-17 -0.0042221"/>
      <mass value="0.34065"/>
      <inertia ixx="0.00030696" ixy="1.0391e-20" ixz="1.3553e-20" iyy="0.00030696" iyz="4.616e-21" izz="0.00029643"/>
    </inertial>
    <visual>
      <origin rpy="0 0 0" xyz="0 0 0"/>
      <geometry>
        <mesh filename="package://xm_arm_description/meshes/link_wheel_2.stl"/>
      </geometry>
      <material name="DarkGrey"/>
    </visual>
    <collision>
      <origin rpy="0 0 0" xyz="0 0 0"/>
      <geometry>
        <mesh filename="package://xm_arm_description/meshes/link_wheel_2_l.stl"/>
      </geometry>
    </collision>
  </link>
  <joint name="joint_wheel_3" type="fixed">
    <origin rpy="-1.5708 0 0.5236" xyz="-0.097362 0.1681 -0.042"/>
    <parent link="base_link"/>
    <child link="link_wheel_3"/>
    <axis xyz="0 0 1"/>
  </joint>
  <link name="link_wheel_3">
    <inertial>
      <origin rpy="0 0 0" xyz="1.4572E-15 0 -0.0042221"/>
      <mass value="0.34065"/>
      <inertia ixx="0.00030696" ixy="-3.3256e-21" ixz="2.7105e-20" iyy="0.00030696" iyz="-1.1933e-20" izz="0.00029643"/>
    </inertial>
    <visual>
      <origin rpy="0 0 0" xyz="0 0 0"/>
      <geometry>
        <mesh filename="package://xm_arm_description/meshes/link_wheel_3.stl"/>
      </geometry>
      <material name="DarkGrey"/>
    </visual>
    <collision>
      <origin rpy="0 0 0" xyz="0 0 0"/>
      <geometry>
        <mesh filename="package://xm_arm_description/meshes/link_wheel_3_l.stl"/>
      </geometry>
    </collision>
  </link>
  <!-- Attach the arm -->
  <joint name="joint_lift" type="prismatic">
    <origin rpy="-2.7756E-17 0 -1.5708" xyz="-0.04456 0.00022708 0.72985"/>
    <parent link="base_link"/>
    <child link="link_lift"/>
    <axis xyz="0 0 -1"/>
    <limit effort="500" lower="-0.15" upper="0.15" velocity="1"/>
  </joint>
  <link name="link_lift">
    <inertial>
      <origin rpy="0 0 0" xyz="-8.3267E-17 0.048515 0.0020048"/>
      <mass value="1.7076"/>
      <inertia ixx="0.015015" ixy="2.1531E-18" ixz="-3.952E-19" iyy="0.015774" iyz="-8.1536E-05" izz="0.0028516"/>
    </inertial>
    <visual>
      <origin rpy="0 0 0" xyz="0 0 0"/>
      <geometry>
        <mesh filename="package://xm_arm_description/meshes/link_lift.stl"/>
      </geometry>
      <material name="OffWhite"/>
    </visual>
    <collision>
      <origin rpy="0 0 0" xyz="0 0 0"/>
      <geometry>
        <mesh filename="package://xm_arm_description/meshes/link_lift_l.stl"/>
      </geometry>
    </collision>
  </link>
  <joint name="joint_waist" type="revolute">
    <origin rpy="2.7756E-17 1.3056E-31 -2.8372E-16" xyz="0 0.0945 0.00415"/>
    <parent link="link_lift"/>
    <child link="link_waist"/>
    <axis xyz="0 0 1"/>
    <limit effort="500" lower="-1.047" upper="1.047" velocity="1"/>
  </joint>
  <link name="link_waist">
    <inertial>
      <origin rpy="0 0 0" xyz="0.00035629 0.050223 0.014835"/>
      <mass value="2.2632"/>
      <inertia ixx="0.014881" ixy="2.8517E-05" ixz="-0.00013888" iyy="0.015217" iyz="0.00052947" izz="0.0095668"/>
    </inertial>
    <visual>
      <origin rpy="0 0 0" xyz="0 0 0"/>
      <geometry>
        <mesh filename="package://xm_arm_description/meshes/link_waist.stl"/>
      </geometry>
      <material name="Orange"/>
    </visual>
    <collision>
      <origin rpy="0 0 0" xyz="0 0 0"/>
      <geometry>
        <mesh filename="package://xm_arm_description/meshes/link_waist_l.stl"/>
      </geometry>
    </collision>
  </link>
  <joint name="joint_big_arm" type="revolute">
    <origin rpy="1.5708 -7.7037E-34 1.5708" xyz="0 0.15678 -0.018"/>
    <parent link="link_waist"/>
    <child link="link_big_arm"/>
    <axis xyz="0 0 1"/>
    <limit effort="500" lower="-1.920" upper="1.396" velocity="1"/>
  </joint>
  <link name="link_big_arm">
    <inertial>
      <origin rpy="0 0 0" xyz="0.095008 0.006168 0.0026321"/>
      <mass value="1.2241"/>
      <inertia ixx="0.0030013" ixy="0.00024375" ixz="0.0004659" iyy="0.017469" iyz="-1.9873E-05" izz="0.015447"/>
    </inertial>
    <visual>
      <origin rpy="0 0 0" xyz="0 0 0"/>
      <geometry>
        <mesh filename="package://xm_arm_description/meshes/link_big_arm.stl"/>
      </geometry>
      <material name="OffWhite"/>
    </visual>
    <collision>
      <origin rpy="0 0 0" xyz="0 0 0"/>
      <geometry>
        <mesh filename="package://xm_arm_description/meshes/link_big_arm_l.stl"/>
      </geometry>
    </collision>
  </link>
  <joint name="joint_forearm" type="revolute">
    <origin rpy="-6.4095E-31 2.2204E-16 -7.7037E-34" xyz="0.35 0 0"/>
    <parent link="link_big_arm"/>
    <child link="link_forearm"/>
    <axis xyz="0 0 -1"/>
    <limit effort="500" lower="-2.234" upper="2.234" velocity="1"/>
  </joint>
  <link name="link_forearm">
    <inertial>
      <origin rpy="0 0 0" xyz="0.099759 -2.2204E-16 0.00013669"/>
      <mass value="0.70102"/>
      <inertia ixx="0.00073291" ixy="5.0551E-18" ixz="4.274E-05" iyy="0.0069521" iyz="7.8112E-19" izz="0.0066437"/>
    </inertial>
    <visual>
      <origin rpy="0 0 0" xyz="0 0 0"/>
      <geometry>
        <mesh filename="package://xm_arm_description/meshes/link_forearm.stl"/>
      </geometry>
      <material name="Orange"/>
    </visual>
    <collision>
      <origin rpy="0 0 0" xyz="0 0 0"/>
      <geometry>
        <mesh filename="package://xm_arm_description/meshes/link_forearm_l.stl"/>
      </geometry>
    </collision>
  </link>
  <joint name="joint_wrist_pitching" type="revolute">
    <origin rpy="0 0 1.5708" xyz="0.3 0 0"/>
    <parent link="link_forearm"/>
    <child link="link_wrist_pitching"/>
    <axis xyz="0 0 -1"/>
    <limit effort="500" lower="-2.182" upper="2.182" velocity="1"/>
  </joint>
  <link name="link_wrist_pitching">
    <inertial>
      <origin rpy="0 0 0" xyz="1.7127E-09 -0.00034153 -1.195E-06"/>
      <mass value="0.037514"/>
      <inertia ixx="1.063E-05" ixy="1.0698E-13" ixz="-4.4237E-13" iyy="1.0507E-05" iyz="-1.5531E-11" izz="3.2674E-06"/>
    </inertial>
    <visual>
      <origin rpy="0 0 0" xyz="0 0 0"/>
      <geometry>
        <mesh filename="package://xm_arm_description/meshes/link_wrist_pitching.stl"/>
      </geometry>
      <material name="OffWhite"/>
    </visual>
    <collision>
      <origin rpy="0 0 0" xyz="0 0 0"/>
      <geometry>
        <mesh filename="package://xm_arm_description/meshes/link_wrist_pitching_l.stl"/>
      </geometry>
    </collision>
  </link>
  <joint name="joint_wrist_rotation" type="continuous">
    <origin rpy="1.5708 -1.5708 0" xyz="0 0 0"/>
    <parent link="link_wrist_pitching"/>
    <child link="link_wrist_rotation"/>
    <axis xyz="0 0 1"/>
    <limit effort="500" velocity="1"/>
  </joint>
  <link name="link_wrist_rotation">
    <inertial>
      <origin rpy="0 0 0" xyz="0.00041743 -0.00042922 0.069037"/>
      <mass value="0.12901"/>
      <inertia ixx="0.00010496" ixy="-2.1936E-07" ixz="5.5636E-07" iyy="0.00011251" iyz="-1.2571E-06" izz="3.1759E-05"/>
    </inertial>
    <visual>
      <origin rpy="0 0 0" xyz="0 0 0"/>
      <geometry>
        <mesh filename="package://xm_arm_description/meshes/link_wrist_rotation.stl"/>
      </geometry>
      <material name="OffWhite"/>
    </visual>
    <collision>
      <origin rpy="0 0 0" xyz="0 0 0"/>
      <geometry>
        <mesh filename="package://xm_arm_description/meshes/link_wrist_rotation_l.stl"/>
      </geometry>
    </collision>
  </link>
  <!-- Attach the gripper -->
  <joint name="joint_finger_left" type="revolute">
    <origin rpy="1.5708 -1.5708 0" xyz="-0.01295 -0.00014458 0.091042"/>
    <parent link="link_wrist_rotation"/>
    <child link="link_finger_left"/>
    <axis xyz="0 0 -1"/>
    <limit effort="500" lower="-1.571" upper="0" velocity="1"/>
  </joint>
  <link name="link_finger_left">
    <inertial>
      <origin rpy="0 0 0" xyz="0.067181 0.0073582 -2.014E-08"/>
      <mass value="0.054127"/>
      <inertia ixx="1.3972E-05" ixy="-3.6354E-06" ixz="-1.1594E-10" iyy="5.1741E-05" iyz="-1.601E-12" izz="4.3944E-05"/>
    </inertial>
    <visual>
      <origin rpy="0 0 0" xyz="0 0 0"/>
      <geometry>
        <mesh filename="package://xm_arm_description/meshes/link_finger_left.stl"/>
      </geometry>
      <material name="Orange"/>
    </visual>
    <collision>
      <origin rpy="0 0 0" xyz="0 0 0"/>
      <geometry>
        <mesh filename="package://xm_arm_description/meshes/link_finger_left_l.stl"/>
      </geometry>
    </collision>
  </link>
  <joint name="joint_finger_right" type="revolute">
    <origin rpy="1.5708 -1.5708 0" xyz="0.01295 -0.00014458 0.091042"/>
    <parent link="link_wrist_rotation"/>
    <child link="link_finger_right"/>
    <axis xyz="0 0 -1"/>
    <limit effort="500" lower="0" upper="1.571" velocity="1"/>
  </joint>
  <link name="link_finger_right">
    <inertial>
      <origin rpy="0 0 0" xyz="0.067181 -0.0073582 2.014E-08"/>
      <mass value="0.054127"/>
      <inertia ixx="1.3972E-05" ixy="3.6354E-06" ixz="1.1594E-10" iyy="5.1741E-05" iyz="-1.601E-12" izz="4.3944E-05"/>
    </inertial>
    <visual>
      <origin rpy="0 0 0" xyz="0 0 0"/>
      <geometry>
        <mesh filename="package://xm_arm_description/meshes/link_finger_right.stl"/>
      </geometry>
      <material name="Orange"/>
    </visual>
    <collision>
      <origin rpy="0 0 0" xyz="0 0 0"/>
      <geometry>
        <mesh filename="package://xm_arm_description/meshes/link_finger_right_l.stl"/>
      </geometry>
    </collision>
  </link>
  <joint name="joint_gripper_frame" type="fixed">
    <origin rpy="0 0 0" xyz="0 0 0.16"/>
    <parent link="link_wrist_rotation"/>
    <child link="link_gripper_frame"/>
  </joint>
  <link name="link_gripper_frame">
    <inertial>
      <origin rpy="0 0 0" xyz="0 0 0"/>
      <mass value="0.0001"/>
      <inertia ixx="0.0" ixy="0.0" ixz="0.0" iyy="0.0" iyz="0.0" izz="0.0"/>
    </inertial>
  </link>
  <!-- Attach the kinect -->
  <joint name="joint_kinect" type="fixed">
    <origin rpy="1.5708 0 -6.1679E-17" xyz="-0.06656 0.00022708 1.1145"/>
    <parent link="base_link"/>
    <child link="link_kinect"/>
    <axis xyz="0 0 1"/>
    <limit effort="500" lower="-0.523" upper="0.523" velocity="1"/>
  </joint>
  <link name="link_kinect">
    <inertial>
      <origin rpy="0 0 0" xyz="0.00024993 -0.00050157 -3.2753E-09"/>
      <mass value="1.3398"/>
      <inertia ixx="0.007821" ixy="-3.6481E-06" ixz="1.9233E-11" iyy="0.0080704" iyz="7.704E-11" izz="0.00058859"/>
    </inertial>
    <visual>
      <origin rpy="0 0 0" xyz="0 0 0"/>
      <geometry>
        <mesh filename="package://xm_arm_description/meshes/link_kinect.stl"/>
      </geometry>
      <material name="DarkGrey"/>
    </visual>
    <collision>
      <origin rpy="0 0 0" xyz="0 0 0"/>
      <geometry>
        <mesh filename="package://xm_arm_description/meshes/link_kinect_l.stl"/>
      </geometry>
    </collision>
  </link>
  <!-- Attach the laser -->
  <joint name="joint_laser" type="fixed">
    <origin rpy="-6.7054E-18 6.9389E-17 -1.5708" xyz="0.20674 0.00022708 0.181"/>
    <parent link="base_link"/>
    <child link="link_laser"/>
    <axis xyz="0 0 0"/>
  </joint>
  <link name="link_laser">
    <inertial>
      <origin rpy="0 0 0" xyz="0 -3.8367E-05 -0.0055273"/>
      <mass value="0.1221"/>
      <inertia ixx="6.4774E-05" ixy="-4.322E-13" ixz="7.0123E-21" iyy="6.4681E-05" iyz="-1.0865E-07" izz="3.7788E-05"/>
    </inertial>
    <visual>
      <origin rpy="0 0 0" xyz="0 0 0"/>
      <geometry>
        <mesh filename="package://xm_arm_description/meshes/link_laser.stl"/>
      </geometry>
      <material name="DarkGrey"/>
    </visual>
    <collision>
      <origin rpy="0 0 0" xyz="0 0 0"/>
      <geometry>
        <mesh filename="package://xm_arm_description/meshes/link_laser_l.stl"/>
      </geometry>
    </collision>
  </link>
  <gazebo reference="base_link">
    <kp>10000.0</kp>
    <kd>10.0</kd>
    <mu1>0.1</mu1>
    <mu2>0.1</mu2>
    <fdir1>1 0 0</fdir1>
    <maxVel>10.0</maxVel>
    <minDepth>0.0005</minDepth>
    <material>Gazebo/Grey</material>
  </gazebo>
  <gazebo reference="link_wheel_1">
    <kp>500000.0</kp>
    <kd>10.0</kd>
    <mu1>10</mu1>
    <mu2>10</mu2>
    <fdir1>1 0 0</fdir1>
    <maxVel>1.0</maxVel>
    <minDepth>0.003</minDepth>
    <material>Gazebo/Grey</material>
  </gazebo>
  <gazebo reference="link_wheel_2">
    <kp>500000.0</kp>
    <kd>10.0</kd>
    <mu1>10</mu1>
    <mu2>10</mu2>
    <fdir1>1 0 0</fdir1>
    <maxVel>1.0</maxVel>
    <minDepth>0.003</minDepth>
    <material>Gazebo/Grey</material>
  </gazebo>
  <gazebo reference="link_wheel_3">
    <kp>500000.0</kp>
    <kd>10.0</kd>
    <mu1>10</mu1>
    <mu2>10</mu2>
    <fdir1>1 0 0</fdir1>
    <maxVel>1.0</maxVel>
    <minDepth>0.003</minDepth>
    <material>Gazebo/Grey</material>
  </gazebo>
  <gazebo reference="joint_wheel_1">
    <implicitSpringDamper>1</implicitSpringDamper>
  </gazebo>
  <gazebo reference="joint_wheel_2">
    <implicitSpringDamper>1</implicitSpringDamper>
  </gazebo>
  <gazebo reference="joint_wheel_3">
    <implicitSpringDamper>1</implicitSpringDamper>
  </gazebo>
  <gazebo reference="link_lift">
    <material>Gazebo/White</material>
  </gazebo>
  <gazebo reference="link_waist">
    <material>Gazebo/Orange</material>
  </gazebo>
  <gazebo reference="link_big_arm">
    <material>Gazebo/White</material>
  </gazebo>
  <gazebo reference="link_forearm">
    <material>Gazebo/Orange</material>
  </gazebo>
  <gazebo reference="link_wrist_pitching">
    <material>Gazebo/White</material>
  </gazebo>
  <gazebo reference="link_wrist_rotation">
    <material>Gazebo/White</material>
  </gazebo>
  <gazebo reference="link_finger_left">
    <kp>1000000.0</kp>
    <kd>100.0</kd>
    <mu1>30.0</mu1>
    <mu2>30.0</mu2>
    <maxVel>1.0</maxVel>
    <minDepth>0.001</minDepth>
    <material>Gazebo/Orange</material>
  </gazebo>
  <gazebo reference="link_finger_right">
    <kp>1000000.0</kp>
    <kd>100.0</kd>
    <mu1>30.0</mu1>
    <mu2>30.0</mu2>
    <maxVel>1.0</maxVel>
    <minDepth>0.001</minDepth>
    <material>Gazebo/Orange</material>
  </gazebo>
  <gazebo reference="link_gripper_frame">
    <material>Gazebo/White</material>
  </gazebo>
  <gazebo reference="link_laser">
    <material>Gazebo/Grey</material>
  </gazebo>
  <gazebo reference="link_kinect">
    <material>Gazebo/Grey</material>
  </gazebo>
  <gazebo reference="link_kinect">
    <sensor name="kinect" type="depth">
      <update_rate>20</update_rate>
      <camera>
        <horizontal_fov>1.0471975512</horizontal_fov>
        <image>
          <format>R8G8B8</format>
          <width>640</width>
          <height>480</height>
        </image>
        <clip>
          <near>0.5</near>
          <far>9</far>
        </clip>
      </camera>
      <plugin filename="libgazebo_ros_openni_kinect.so" name="kinect_controller">
        <baseline>0.1</baseline>
        <alwaysOn>true</alwaysOn>
        <updateRate>15.0</updateRate>
        <cameraName>head_kinect</cameraName>
        <imageTopicName>/head_kinect/rgb/image_raw</imageTopicName>
        <cameraInfoTopicName>/head_kinect/rgb/camera_info</cameraInfoTopicName>
        <depthImageTopicName>/head_kinect/depth/image_raw</depthImageTopicName>
        <depthImageCameraInfoTopicName>/head_kinect/depth/camera_info</depthImageCameraInfoTopicName>
        <pointCloudTopicName>/head_kinect/depth/points</pointCloudTopicName>
        <frameName>link_kinect_depth</frameName>
        <pointCloudCutoff>0.35</pointCloudCutoff>
        <distortionK1>0.00000001</distortionK1>
        <distortionK2>0.00000001</distortionK2>
        <distortionK3>0.00000001</distortionK3>
        <distortionT1>0.00000001</distortionT1>
        <distortionT2>0.00000001</distortionT2>
        <CxPrime>0</CxPrime>
        <Cx>0</Cx>
        <Cy>0</Cy>
        <focalLength>0</focalLength>
        <hackBaseline>0</hackBaseline>
      </plugin>
    </sensor>
  </gazebo>
  <transmission name="lift_simp_tran">
    <type>transmission_interface/SimpleTransmission</type>
    <joint name="joint_lift">
      <hardwareInterface>PositionJointInterface</hardwareInterface>
    </joint>
    <actuator name="lift_motor">
      <hardwareInterface>PositionJointInterface</hardwareInterface>
      <mechanicalReduction>1</mechanicalReduction>
    </actuator>
  </transmission>
  <transmission name="waist_simp_tran">
    <type>transmission_interface/SimpleTransmission</type>
    <joint name="joint_waist">
      <hardwareInterface>PositionJointInterface</hardwareInterface>
    </joint>
    <actuator name="waist_motor">
      <hardwareInterface>PositionJointInterface</hardwareInterface>
      <mechanicalReduction>1</mechanicalReduction>
    </actuator>
  </transmission>
  <transmission name="big_arm_simp_tran">
    <type>transmission_interface/SimpleTransmission</type>
    <joint name="joint_big_arm">
      <hardwareInterface>PositionJointInterface</hardwareInterface>
    </joint>
    <actuator name="big_arm_motor">
      <hardwareInterface>PositionJointInterface</hardwareInterface>
      <mechanicalReduction>1</mechanicalReduction>
    </actuator>
  </transmission>
  <transmission name="forearm_simp_tran">
    <type>transmission_interface/SimpleTransmission</type>
    <joint name="joint_forearm">
      <hardwareInterface>PositionJointInterface</hardwareInterface>
    </joint>
    <actuator name="forearm_motor">
      <hardwareInterface>PositionJointInterface</hardwareInterface>
      <mechanicalReduction>1</mechanicalReduction>
    </actuator>
  </transmission>
  <transmission name="wrist_pitching_simp_tran">
    <type>transmission_interface/SimpleTransmission</type>
    <joint name="joint_wrist_pitching">
      <hardwareInterface>PositionJointInterface</hardwareInterface>
    </joint>
    <actuator name="wrist_motor_1">
      <hardwareInterface>PositionJointInterface</hardwareInterface>
      <mechanicalReduction>1</mechanicalReduction>
    </actuator>
  </transmission>
  <transmission name="wrist_rotation_simp_tran">
    <type>transmission_interface/SimpleTransmission</type>
    <joint name="joint_wrist_rotation">
      <hardwareInterface>PositionJointInterface</hardwareInterface>
    </joint>
    <actuator name="wrist_motor_2">
      <hardwareInterface>PositionJointInterface</hardwareInterface>
      <mechanicalReduction>1</mechanicalReduction>
    </actuator>
  </transmission>
  <transmission name="finger_left_simp_tran">
    <type>transmission_interface/SimpleTransmission</type>
    <joint name="joint_finger_left">
      <hardwareInterface>PositionJointInterface</hardwareInterface>
    </joint>
    <actuator name="finger_left_servo">
      <hardwareInterface>PositionJointInterface</hardwareInterface>
      <mechanicalReduction>1</mechanicalReduction>
    </actuator>
  </transmission>
  <transmission name="finger_right_simp_tran">
    <type>transmission_interface/SimpleTransmission</type>
    <joint name="joint_finger_right">
      <hardwareInterface>PositionJointInterface</hardwareInterface>
    </joint>
    <actuator name="finger_right_servo">
      <hardwareInterface>PositionJointInterface</hardwareInterface>
      <mechanicalReduction>1</mechanicalReduction>
    </actuator>
  </transmission>
  <gazebo>
    <plugin filename="libgazebo_ros_control.so" name="gazebo_ros_control">
      <robotNamespace>/xm_arm</robotNamespace>
      <robotSimType>gazebo_ros_control/DefaultRobotHWSim</robotSimType>
    </plugin>
  </gazebo>
</robot>

